<robot name="s5fs">
    <!-- BASE_LINE LINKS -->
    <link name="base_link">
        <visual>
            <origin rpy="0 0 0" xyz="0 0.01313 0" />
            <geometry>
                <box size="0.0353 0.02626 0.010" />
            </geometry>
            <material name="green">
                <color rgba="0 1 0 1" />
            </material>
        </visual>
    </link>
    <link name="d">
        <visual>
            <origin rpy="0 0 0" xyz="0 0 0.055" />
            <geometry>
                <cylinder length="0.110" radius="0.001" />
            </geometry>
            <material name="green" />
        </visual>
    </link>
    <link name="h">
        <visual>
            <origin rpy="0 1.571 0" xyz="-0.0125 0 0.0825" />
            <geometry>
                <cylinder length="0.025" radius="0.001" />
            </geometry>
            <material name="green" />
        </visual>
    </link>
    <link name="d2">
        <visual>
            <origin rpy="0 0 0" xyz="-0.025 0 0.09625" />
            <geometry>
                <cylinder length="0.0275" radius="0.001" />
            </geometry>
            <material name="green" />
        </visual>
    </link>
    <!-- LENGTH NOT FOUND IN DATASHEET! GUESSED!!! -->
    <link name="e1">
        <visual>
            <origin rpy="0 0 0" xyz="0.01840 0 0.01875" />
            <geometry>
                <cylinder length="0.0375" radius="0.001" />
            </geometry>
            <material name="green" />
        </visual>
    </link>
    <!-- LENGTH NOT FOUND IN DATASHEET! GUESSED!!! -->
    <link name="e2">
        <visual>
            <origin rpy="0 1.571 0" xyz="0.00875 0 0" />
            <geometry>
                <cylinder length="0.0175" radius="0.001" />
            </geometry>
            <material name="green" />
        </visual>
    </link>
    <!-- LENGTH NOT FOUND IN DATASHEET! GUESSED!!! -->
    <link name="e3">
        <visual>
            <origin rpy="0 0 0" xyz="0.0175 0 0.015" />
            <geometry>
                <cylinder length="0.03" radius="0.001" />
            </geometry>
            <material name="green" />
        </visual>
    </link>
    <link name="e">
        <visual>
            <origin rpy="0 1.571 0" xyz="0.0175 0 0.03" />
            <geometry>
                <cylinder length="0.0215" radius="0.001" />
            </geometry>
            <material name="green" />
        </visual>
    </link>
    <!-- LENGTH NOT FOUND IN DATASHEET! GUESSED, BUT POSITION CALCULATED: E4 = D-G-F!!! -->
    <link name="e4">
        <visual>
            <origin rpy="0 0 0" xyz="0.02825 0 0.043" />
            <geometry>
                <cylinder length="0.026" radius="0.001" />
            </geometry>
            <material name="green" />
        </visual>
    </link>
    <!-- LENGTH NOT FOUND IN DATASHEET! GUESSED, BUT POSITION CALCULATED: E5 = D-G!!! -->
    <link name="e5">
        <visual>
            <origin rpy="0 0 0" xyz="0.00675 0 0.04775" />
            <geometry>
                <cylinder length="0.0355" radius="0.001" />
            </geometry>
            <material name="green" />
        </visual>
    </link>


    <!-- THUMB LINKS -->
    <link name="z">
        <visual>
            <origin rpy="0 0 0" xyz="0 0 0.02298" />
            <geometry>
                <cylinder length="0.04596" radius="0.001" />
            </geometry>
            <material name="green" />
        </visual>
    </link>
    <link name="a">
        <visual>
            <origin rpy="0 0 0" xyz="0 0 0.02425" />
            <geometry>
                <cylinder length="0.0485" radius="0.001" />
            </geometry>
            <material name="green" />
        </visual>
    </link>
    <link name="b">
        <visual>
            <origin rpy="0 0 0" xyz="0 0 0.015" />
            <geometry>
                <cylinder length="0.030" radius="0.001" />
            </geometry>
            <material name="green" />
        </visual>
    </link>
    <link name="c">
        <visual>
            <origin rpy="0 0 0" xyz="0 0 0.010" />
            <geometry>
                <cylinder length="0.020" radius="0.001" />
            </geometry>
            <material name="green" />
        </visual>
    </link>


    <!-- FOREFINGER LINKS -->
    <link name="virtual_l">
        <visual>
            <origin rpy="0 0 0" xyz="0 0 0" />
            <geometry>
                <cylinder length="0" radius="0" />
            </geometry>
        </visual>
    </link>
    <link name="l">
        <visual>
            <origin rpy="0 0 0" xyz="0 0 0.02402" />
            <geometry>
                <cylinder length="0.04804" radius="0.001" />
            </geometry>
            <material name="green" />
        </visual>
    </link>
    <link name="p">
        <visual>
            <origin rpy="0 0 0" xyz="0 0 0.013" />
            <geometry>
                <cylinder length="0.026" radius="0.001" />
            </geometry>
            <material name="green" />
        </visual>
    </link>
    <link name="t">
        <visual>
            <origin rpy="0 0 0" xyz="0 0 0.0075" />
            <geometry>
                <cylinder length="0.015" radius="0.001" />
            </geometry>
            <material name="green" />
        </visual>
    </link>


    <!-- MIDDLE FINGER LINKS -->
    <link name="k">
        <visual>
            <origin rpy="0 0 0" xyz="0 0 0.02502" />
            <geometry>
                <cylinder length="0.05004" radius="0.001" />
            </geometry>
            <material name="green" />
        </visual>
    </link>
    <link name="o">
        <visual>
            <origin rpy="0 0 0" xyz="0 0 0.016" />
            <geometry>
                <cylinder length="0.032" radius="0.001" />
            </geometry>
            <material name="green" />
        </visual>
    </link>
    <link name="s">
        <visual>
            <origin rpy="0 0 0" xyz="0 0 0.0075" />
            <geometry>
                <cylinder length="0.015" radius="0.001" />
            </geometry>
            <material name="green" />
        </visual>
    </link>


    <!-- RING FINGER LINKS -->
    <link name="virtual_j">
        <visual>
            <origin rpy="0 0 0" xyz="0.006625 0 0" />
            <geometry>
                <cylinder length="0" radius="0" />
            </geometry>
        </visual>
    </link>
    <link name="j">
        <visual>
            <origin rpy="0 0 0" xyz="0 0 0.02502" />
            <geometry>
                <cylinder length="0.05004" radius="0.001" />
            </geometry>
            <material name="green" />
        </visual>
    </link>
    <link name="n">
        <visual>
            <origin rpy="0 0 0" xyz="0 0 0.01525" />
            <geometry>
                <cylinder length="0.032" radius="0.001" />
            </geometry>
            <material name="green" />
        </visual>
    </link>
    <link name="r">
        <visual>
            <origin rpy="0 0 0" xyz="0 0 0.00675" />
            <geometry>
                <cylinder length="0.015" radius="0.001" />
            </geometry>
            <material name="green" />
        </visual>
    </link>


    <!-- LITTLE FINGER LINKS -->
    <link name="virtual_i">
        <visual>
            <origin rpy="0 0 0" xyz="0.02825 0 0" />
            <geometry>
                <cylinder length="0" radius="0" />
            </geometry>
        </visual>
    </link>
    <link name="i">
        <visual>
            <origin rpy="0 0 0" xyz="0 0 0.02227" />
            <geometry>
                <cylinder length="0.04454" radius="0.001" />
            </geometry>
            <material name="green" />
        </visual>
    </link>
    <link name="m">
        <visual>
            <origin rpy="0 0 0" xyz="0 0 0.011" />
            <geometry>
                <cylinder length="0.022" radius="0.001" />
            </geometry>
            <material name="green" />
        </visual>
    </link>
    <link name="q">
        <visual>
            <origin rpy="0 0 0" xyz="0 0 0.0075" />
            <geometry>
                <cylinder length="0.015" radius="0.001" />
            </geometry>
            <material name="green" />
        </visual>
    </link>






    <!-- BASE_LINE JOINTS -->
    <joint name="j1_wrist" type="revolute">
        <parent link="base_link" />
        <child link="z" />
        <limit effort="1000.0" lower="0.0" upper="0.9879" velocity="1" />
        <origin xyz="-0.01690 0.02626 0" rpy="0 0.2618 1.571" />
        <axis xyz="0 0 -1" />
    </joint>

    <joint name="j6b_spread" type="revolute">
        <parent link="virtual_l" />
        <child link="l" />
        <limit effort="1000.0" lower="0.0" upper="0.28833" velocity="1" />
        <origin xyz="0 0 0" rpy="0 0 0" />
        <axis xyz="0 -1 0" />
    </joint>


    <joint name="f1" type="fixed">
        <parent link="base_link" />
        <child link="d" />
        <origin xyz="0 0 0" rpy="0 0 0" />
    </joint>
    <joint name="f2" type="fixed">
        <parent link="d" />
        <child link="h" />
        <origin xyz="0 0 0" rpy="0 0 0" />
    </joint>
    <joint name="f3" type="fixed">
        <parent link="h" />
        <child link="d2" />
        <origin xyz="0 0 0" rpy="0 0 0" />
    </joint>
    <joint name="f4" type="fixed">
        <parent link="base_link" />
        <child link="e1" />
        <origin xyz="0 0 0" rpy="0 0 0" />
    </joint>
    <joint name="j5" type="revolute">
        <parent link="e1" />
        <child link="e2" />
        <limit effort="1000.0" lower="0.0" upper="0.98786" velocity="1" />
        <origin xyz="0.01840 0 0.0375" rpy="0 0 0" />
        <axis xyz="0 0 1" />
        <mimic joint="j1_wrist" multiplier="1" offset="0" />
    </joint>
    <joint name="f5" type="fixed">
        <parent link="e2" />
        <child link="e3" />
        <origin xyz="0 0 0" rpy="0 0 0" />
    </joint>
    <joint name="f6" type="fixed">
        <parent link="e3" />
        <child link="e" />
        <origin xyz="0 0 0" rpy="0 0 0" />
    </joint>
    <joint name="f7" type="fixed">
        <parent link="e" />
        <child link="e4" />
        <origin xyz="0 0 0" rpy="0 0 0" />
    </joint>
    <joint name="f8" type="fixed">
        <parent link="e" />
        <child link="e5" />
        <origin xyz="0 0 0" rpy="0 0 0" />
    </joint>


    <!-- THUMB JOINTS -->
    <joint name="j2_thumb" type="revolute">
        <parent link="z" />
        <child link="a" />
        <limit effort="1000.0" lower="0.0" upper="0.9704" velocity="1" />
        <origin xyz="0 0 0.04596" rpy="0 0 0" />
        <axis xyz="1 0 0" />
    </joint>
    <joint name="j3" type="revolute">
        <parent link="a" />
        <child link="b" />
        <limit effort="1000.0" lower="0.0" upper="0.98506" velocity="1" />
        <origin xyz="0 0 0.0485" rpy="0 0 0" />
        <axis xyz="1 0 0" />
        <mimic joint="j2_thumb" multiplier="1.01511" offset="0" />
    </joint>
    <joint name="j4" type="revolute">
        <parent link="b" />
        <child link="c" />
        <limit effort="1000.0" lower="0.0" upper="1.406" velocity="1" />
        <origin xyz="0 0 0.030" rpy="0 0 0" />
        <axis xyz="1 0 0" />
        <mimic joint="j2_thumb" multiplier="1.44889" offset="0" />
    </joint>


    <!-- FOREFINGER JOINTS -->
    <joint name="j6a_forefinger1" type="revolute">
        <parent link="d2" />
        <child link="virtual_l" />
        <limit effort="1000.0" lower="0.0" upper="0.79849" velocity="1" />
        <origin xyz="-0.025 0 0.110" rpy="0 0 0" />
        <axis xyz="-1 0 0" />
    </joint>
    <joint name="j10_forefinger2" type="revolute">
        <parent link="l" />
        <child link="p" />
        <limit effort="1000.0" lower="0" upper="1.334" velocity="1" />
        <origin xyz="0 0 0.04804" rpy="0 0 0" />
        <axis xyz="-1 0 0" />
    </joint>
    <joint name="j14" type="revolute">
        <parent link="p" />
        <child link="t" />
        <limit effort="1000.0" lower="0" upper="1.394" velocity="1" />
        <origin xyz="0 0 0.026" rpy="0 0 0" />
        <axis xyz="-1 0 0" />
        <mimic joint="j10_forefinger2" multiplier="1.0450" offset="0" />
    </joint>


    <!-- MIDDLE FINGER JOINTS -->
    <joint name="j7_middlefinger1" type="revolute">
        <parent link="d" />
        <child link="k" />
        <limit effort="1000.0" lower="0.0" upper="0.79849" velocity="1" />
        <origin xyz="0 0 0.110" rpy="0 0 0" />
        <axis xyz="-1 0 0" />
    </joint>
    <joint name="j11_middlefinger2" type="revolute">
        <parent link="k" />
        <child link="o" />
        <limit effort="1000.0" lower="0" upper="1.334" velocity="1" />
        <origin xyz="0 0 0.05004" rpy="0 0 0" />
        <axis xyz="-1 0 0" />
    </joint>
    <joint name="j15" type="revolute">
        <parent link="o" />
        <child link="s" />
        <limit effort="1000.0" lower="0" upper="1.334" velocity="1" />
        <origin xyz="0 0 0.032" rpy="0 0 0" />
        <axis xyz="-1 0 0" />
        <mimic joint="j11_middlefinger2" multiplier="1.000" offset="0" />
    </joint>


    <!-- RING FINGER JOINTS -->
    <joint name="j8a_ringfinger" type="revolute">
        <parent link="e5" />
        <child link="virtual_j" />
        <limit effort="1000.0" lower="0.0" upper="0.98175" velocity="1" />
        <origin xyz="0 0 0.0655" rpy="0 0 0" />
        <axis xyz="-1 0 0" />
    </joint>
    <joint name="j8b" type="revolute">
        <parent link="virtual_j" />
        <child link="j" />
        <limit effort="1000.0" lower="0.0" upper="0.28833" velocity="1" />
        <origin xyz="0.00675 0 0" rpy="0 0 0" />
        <axis xyz="0 1 0" />
        <mimic joint="j6b_spread" multiplier="1" offset="0" />
    </joint>
    <joint name="j12" type="revolute">
        <parent link="j" />
        <child link="n" />
        <limit effort="1000.0" lower="0" upper="1.334" velocity="1" />
        <origin xyz="0 0 0.05004" rpy="0 0 0" />
        <axis xyz="-1 0 0" />
        <mimic joint="j8a_ringfinger" multiplier="1.3588" offset="0" />
    </joint>
    <joint name="j16" type="revolute">
        <parent link="n" />
        <child link="r" />
        <limit effort="1000.0" lower="0" upper="1.395" velocity="1" />
        <origin xyz="0 0 0.032" rpy="0 0 0" />
        <axis xyz="-1 0 0" />
        <mimic joint="j8a_ringfinger" multiplier="1.42093" offset="0" />
    </joint>


    <!-- LITTLE FINGER JOINTS -->
    <joint name="j9a_littlefinger" type="revolute">
        <parent link="e4" />
        <child link="virtual_i" />
        <limit effort="1000.0" lower="0.0" upper="0.98175" velocity="1" />
        <origin xyz="0 0 0.056" rpy="0 0 0" />
        <axis xyz="-1 0 0" />
    </joint>
    <joint name="j9b" type="revolute">
        <parent link="virtual_i" />
        <child link="i" />
        <limit effort="1000.0" lower="0.0" upper="0.5829" velocity="1" />
        <origin xyz="0.02825 0 0" rpy="0 0 0" />
        <axis xyz="0 1 0" />
        <mimic joint="j6b_spread" multiplier="2.02164" offset="0" />
    </joint>
    <joint name="j13" type="revolute">
        <parent link="i" />
        <child link="m" />
        <limit effort="1000.0" lower="0" upper="1.334" velocity="1" />
        <origin xyz="0 0 0.04454" rpy="0 0 0" />
        <axis xyz="-1 0 0" />
        <mimic joint="j9a_littlefinger" multiplier="1.35880" offset="0" />
    </joint>
    <joint name="j17" type="revolute">
        <parent link="m" />
        <child link="q" />
        <limit effort="1000.0" lower="0" upper="1.3971" velocity="1" />
        <origin xyz="0 0 0.022" rpy="0 0 0" />
        <axis xyz="-1 0 0" />
        <mimic joint="j9a_littlefinger" multiplier="1.42307" offset="0" />
    </joint>
</robot>
